Exception on /list_decoded/EN/ [POST]
Traceback (most recent call last):
  File "C:\ильнур\flask-factory\app\processing\processors.py", line 16, in process_airports
    from_airport  = config.AIRPORTS[from_airport]
KeyError: '4'

During handling of the above exception, another exception occurred:

Traceback (most recent call last):
  File "C:\Users\Roman\AppData\Local\Programs\Python\Python38-32\lib\site-packages\flask\app.py", line 2446, in wsgi_app
    response = self.full_dispatch_request()
  File "C:\Users\Roman\AppData\Local\Programs\Python\Python38-32\lib\site-packages\flask\app.py", line 1951, in full_dispatch_request
    rv = self.handle_user_exception(e)
  File "C:\Users\Roman\AppData\Local\Programs\Python\Python38-32\lib\site-packages\flask\app.py", line 1820, in handle_user_exception
    reraise(exc_type, exc_value, tb)
  File "C:\Users\Roman\AppData\Local\Programs\Python\Python38-32\lib\site-packages\flask\_compat.py", line 39, in reraise
    raise value
  File "C:\Users\Roman\AppData\Local\Programs\Python\Python38-32\lib\site-packages\flask\app.py", line 1949, in full_dispatch_request
    rv = self.dispatch_request()
  File "C:\Users\Roman\AppData\Local\Programs\Python\Python38-32\lib\site-packages\flask\app.py", line 1935, in dispatch_request
    return self.view_functions[rule.endpoint](**req.view_args)
  File "C:\ильнур\flask-factory\app\codes\routes.py", line 19, in list_decoded
    out = gdsdecoder.decode_gds(line)
  File "C:\ильнур\flask-factory\app\processing\gdsdecoder.py", line 14, in decode_gds
    processors.process_airports(from_to_airports,decoded)
  File "C:\ильнур\flask-factory\app\processing\processors.py", line 19, in process_airports
    current_app.logging.info("Wrong case : 3 to 4")
  File "C:\Users\Roman\AppData\Local\Programs\Python\Python38-32\lib\site-packages\werkzeug\local.py", line 347, in __getattr__
    return getattr(self._get_current_object(), name)
AttributeError: 'Flask' object has no attribute 'logging'
Wrong case : 3 to 4
Wrong case : 4 to 3
No matching airports
Exception on /list_decoded/EN/ [POST]
Traceback (most recent call last):
  File "C:\ильнур\flask-factory\app\processing\processors.py", line 16, in process_airports
    from_airport  = config.AIRPORTS[from_airport]
KeyError: '4'

During handling of the above exception, another exception occurred:

Traceback (most recent call last):
  File "C:\ильнур\flask-factory\app\processing\processors.py", line 24, in process_airports
    from_airport  = config.AIRPORTS[from_airport]
KeyError: '4'

During handling of the above exception, another exception occurred:

Traceback (most recent call last):
  File "C:\Users\Roman\AppData\Local\Programs\Python\Python38-32\lib\site-packages\flask\app.py", line 2446, in wsgi_app
    response = self.full_dispatch_request()
  File "C:\Users\Roman\AppData\Local\Programs\Python\Python38-32\lib\site-packages\flask\app.py", line 1951, in full_dispatch_request
    rv = self.handle_user_exception(e)
  File "C:\Users\Roman\AppData\Local\Programs\Python\Python38-32\lib\site-packages\flask\app.py", line 1820, in handle_user_exception
    reraise(exc_type, exc_value, tb)
  File "C:\Users\Roman\AppData\Local\Programs\Python\Python38-32\lib\site-packages\flask\_compat.py", line 39, in reraise
    raise value
  File "C:\Users\Roman\AppData\Local\Programs\Python\Python38-32\lib\site-packages\flask\app.py", line 1949, in full_dispatch_request
    rv = self.dispatch_request()
  File "C:\Users\Roman\AppData\Local\Programs\Python\Python38-32\lib\site-packages\flask\app.py", line 1935, in dispatch_request
    return self.view_functions[rule.endpoint](**req.view_args)
  File "C:\ильнур\flask-factory\app\codes\routes.py", line 19, in list_decoded
    out = gdsdecoder.decode_gds(line)
  File "C:\ильнур\flask-factory\app\processing\gdsdecoder.py", line 14, in decode_gds
    processors.process_airports(from_to_airports,decoded)
  File "C:\ильнур\flask-factory\app\processing\processors.py", line 29, in process_airports
    raise ValueError
ValueError
CASE 1 from_airport:4
CASE 1 to_airport:
Wrong case : 3 to 4
CASE 2 from_airport:4
CASE 2 to_airport:
Wrong case : 4 to 3
No matching airports
Exception on /list_decoded/EN/ [POST]
Traceback (most recent call last):
  File "C:\ильнур\flask-factory\app\processing\processors.py", line 20, in process_airports
    from_airport  = config.AIRPORTS[from_airport]
KeyError: '4'

During handling of the above exception, another exception occurred:

Traceback (most recent call last):
  File "C:\ильнур\flask-factory\app\processing\processors.py", line 33, in process_airports
    from_airport  = config.AIRPORTS[from_airport]
KeyError: '4'

During handling of the above exception, another exception occurred:

Traceback (most recent call last):
  File "C:\Users\Roman\AppData\Local\Programs\Python\Python38-32\lib\site-packages\flask\app.py", line 2446, in wsgi_app
    response = self.full_dispatch_request()
  File "C:\Users\Roman\AppData\Local\Programs\Python\Python38-32\lib\site-packages\flask\app.py", line 1951, in full_dispatch_request
    rv = self.handle_user_exception(e)
  File "C:\Users\Roman\AppData\Local\Programs\Python\Python38-32\lib\site-packages\flask\app.py", line 1820, in handle_user_exception
    reraise(exc_type, exc_value, tb)
  File "C:\Users\Roman\AppData\Local\Programs\Python\Python38-32\lib\site-packages\flask\_compat.py", line 39, in reraise
    raise value
  File "C:\Users\Roman\AppData\Local\Programs\Python\Python38-32\lib\site-packages\flask\app.py", line 1949, in full_dispatch_request
    rv = self.dispatch_request()
  File "C:\Users\Roman\AppData\Local\Programs\Python\Python38-32\lib\site-packages\flask\app.py", line 1935, in dispatch_request
    return self.view_functions[rule.endpoint](**req.view_args)
  File "C:\ильнур\flask-factory\app\codes\routes.py", line 19, in list_decoded
    out = gdsdecoder.decode_gds(line)
  File "C:\ильнур\flask-factory\app\processing\gdsdecoder.py", line 14, in decode_gds
    processors.process_airports(from_to_airports,decoded)
  File "C:\ильнур\flask-factory\app\processing\processors.py", line 39, in process_airports
    raise ValueError
ValueError
CASE 1 from_airport:4
CASE 1 to_airport:
Wrong case : 3 to 4
CASE 2 from_airport:4
CASE 2 to_airport:
Wrong case : 4 to 3
No matching airports
Exception on /list_decoded/EN/ [POST]
Traceback (most recent call last):
  File "C:\ильнур\flask-factory\app\processing\processors.py", line 20, in process_airports
    from_airport  = config.AIRPORTS[from_airport]
KeyError: '4'

During handling of the above exception, another exception occurred:

Traceback (most recent call last):
  File "C:\ильнур\flask-factory\app\processing\processors.py", line 33, in process_airports
    from_airport  = config.AIRPORTS[from_airport]
KeyError: '4'

During handling of the above exception, another exception occurred:

Traceback (most recent call last):
  File "C:\Users\Roman\AppData\Local\Programs\Python\Python38-32\lib\site-packages\flask\app.py", line 2446, in wsgi_app
    response = self.full_dispatch_request()
  File "C:\Users\Roman\AppData\Local\Programs\Python\Python38-32\lib\site-packages\flask\app.py", line 1951, in full_dispatch_request
    rv = self.handle_user_exception(e)
  File "C:\Users\Roman\AppData\Local\Programs\Python\Python38-32\lib\site-packages\flask\app.py", line 1820, in handle_user_exception
    reraise(exc_type, exc_value, tb)
  File "C:\Users\Roman\AppData\Local\Programs\Python\Python38-32\lib\site-packages\flask\_compat.py", line 39, in reraise
    raise value
  File "C:\Users\Roman\AppData\Local\Programs\Python\Python38-32\lib\site-packages\flask\app.py", line 1949, in full_dispatch_request
    rv = self.dispatch_request()
  File "C:\Users\Roman\AppData\Local\Programs\Python\Python38-32\lib\site-packages\flask\app.py", line 1935, in dispatch_request
    return self.view_functions[rule.endpoint](**req.view_args)
  File "C:\ильнур\flask-factory\app\codes\routes.py", line 19, in list_decoded
    out = gdsdecoder.decode_gds(line)
  File "C:\ильнур\flask-factory\app\processing\gdsdecoder.py", line 14, in decode_gds
    processors.process_airports(from_to_airports,decoded)
  File "C:\ильнур\flask-factory\app\processing\processors.py", line 39, in process_airports
    raise ValueError
ValueError
from_to_airports:4
CASE 1 from_airport:4
CASE 1 to_airport:
Wrong case : 3 to 4
CASE 2 from_airport:4
CASE 2 to_airport:
Wrong case : 4 to 3
No matching airports
Exception on /list_decoded/EN/ [POST]
Traceback (most recent call last):
  File "C:\ильнур\flask-factory\app\processing\processors.py", line 21, in process_airports
    from_airport  = config.AIRPORTS[from_airport]
KeyError: '4'

During handling of the above exception, another exception occurred:

Traceback (most recent call last):
  File "C:\ильнур\flask-factory\app\processing\processors.py", line 34, in process_airports
    from_airport  = config.AIRPORTS[from_airport]
KeyError: '4'

During handling of the above exception, another exception occurred:

Traceback (most recent call last):
  File "C:\Users\Roman\AppData\Local\Programs\Python\Python38-32\lib\site-packages\flask\app.py", line 2446, in wsgi_app
    response = self.full_dispatch_request()
  File "C:\Users\Roman\AppData\Local\Programs\Python\Python38-32\lib\site-packages\flask\app.py", line 1951, in full_dispatch_request
    rv = self.handle_user_exception(e)
  File "C:\Users\Roman\AppData\Local\Programs\Python\Python38-32\lib\site-packages\flask\app.py", line 1820, in handle_user_exception
    reraise(exc_type, exc_value, tb)
  File "C:\Users\Roman\AppData\Local\Programs\Python\Python38-32\lib\site-packages\flask\_compat.py", line 39, in reraise
    raise value
  File "C:\Users\Roman\AppData\Local\Programs\Python\Python38-32\lib\site-packages\flask\app.py", line 1949, in full_dispatch_request
    rv = self.dispatch_request()
  File "C:\Users\Roman\AppData\Local\Programs\Python\Python38-32\lib\site-packages\flask\app.py", line 1935, in dispatch_request
    return self.view_functions[rule.endpoint](**req.view_args)
  File "C:\ильнур\flask-factory\app\codes\routes.py", line 19, in list_decoded
    out = gdsdecoder.decode_gds(line)
  File "C:\ильнур\flask-factory\app\processing\gdsdecoder.py", line 14, in decode_gds
    processors.process_airports(from_to_airports,decoded)
  File "C:\ильнур\flask-factory\app\processing\processors.py", line 40, in process_airports
    raise ValueError
ValueError
from_to_airports:4
CASE 1 from_airport:4
CASE 1 to_airport:
Wrong case : 3 to 4
CASE 2 from_airport:4
CASE 2 to_airport:
Wrong case : 4 to 3
No matching airports
Exception on /list_decoded/EN/ [POST]
Traceback (most recent call last):
  File "C:\ильнур\flask-factory\app\processing\processors.py", line 21, in process_airports
    from_airport  = config.AIRPORTS[from_airport]
KeyError: '4'

During handling of the above exception, another exception occurred:

Traceback (most recent call last):
  File "C:\ильнур\flask-factory\app\processing\processors.py", line 34, in process_airports
    from_airport  = config.AIRPORTS[from_airport]
KeyError: '4'

During handling of the above exception, another exception occurred:

Traceback (most recent call last):
  File "C:\Users\Roman\AppData\Local\Programs\Python\Python38-32\lib\site-packages\flask\app.py", line 2446, in wsgi_app
    response = self.full_dispatch_request()
  File "C:\Users\Roman\AppData\Local\Programs\Python\Python38-32\lib\site-packages\flask\app.py", line 1951, in full_dispatch_request
    rv = self.handle_user_exception(e)
  File "C:\Users\Roman\AppData\Local\Programs\Python\Python38-32\lib\site-packages\flask\app.py", line 1820, in handle_user_exception
    reraise(exc_type, exc_value, tb)
  File "C:\Users\Roman\AppData\Local\Programs\Python\Python38-32\lib\site-packages\flask\_compat.py", line 39, in reraise
    raise value
  File "C:\Users\Roman\AppData\Local\Programs\Python\Python38-32\lib\site-packages\flask\app.py", line 1949, in full_dispatch_request
    rv = self.dispatch_request()
  File "C:\Users\Roman\AppData\Local\Programs\Python\Python38-32\lib\site-packages\flask\app.py", line 1935, in dispatch_request
    return self.view_functions[rule.endpoint](**req.view_args)
  File "C:\ильнур\flask-factory\app\codes\routes.py", line 19, in list_decoded
    out = gdsdecoder.decode_gds(line)
  File "C:\ильнур\flask-factory\app\processing\gdsdecoder.py", line 14, in decode_gds
    processors.process_airports(from_to_airports,decoded)
  File "C:\ильнур\flask-factory\app\processing\processors.py", line 40, in process_airports
    raise ValueError
ValueError
from_to_airports:4
CASE 1 from_airport:4
CASE 1 to_airport:
Wrong case : 3 to 4
CASE 2 from_airport:4
CASE 2 to_airport:
Wrong case : 4 to 3
No matching airports
Exception on /list_decoded/EN/ [POST]
Traceback (most recent call last):
  File "C:\ильнур\flask-factory\app\processing\processors.py", line 21, in process_airports
    from_airport  = config.AIRPORTS[from_airport]
KeyError: '4'

During handling of the above exception, another exception occurred:

Traceback (most recent call last):
  File "C:\ильнур\flask-factory\app\processing\processors.py", line 34, in process_airports
    from_airport  = config.AIRPORTS[from_airport]
KeyError: '4'

During handling of the above exception, another exception occurred:

Traceback (most recent call last):
  File "C:\Users\Roman\AppData\Local\Programs\Python\Python38-32\lib\site-packages\flask\app.py", line 2446, in wsgi_app
    response = self.full_dispatch_request()
  File "C:\Users\Roman\AppData\Local\Programs\Python\Python38-32\lib\site-packages\flask\app.py", line 1951, in full_dispatch_request
    rv = self.handle_user_exception(e)
  File "C:\Users\Roman\AppData\Local\Programs\Python\Python38-32\lib\site-packages\flask\app.py", line 1820, in handle_user_exception
    reraise(exc_type, exc_value, tb)
  File "C:\Users\Roman\AppData\Local\Programs\Python\Python38-32\lib\site-packages\flask\_compat.py", line 39, in reraise
    raise value
  File "C:\Users\Roman\AppData\Local\Programs\Python\Python38-32\lib\site-packages\flask\app.py", line 1949, in full_dispatch_request
    rv = self.dispatch_request()
  File "C:\Users\Roman\AppData\Local\Programs\Python\Python38-32\lib\site-packages\flask\app.py", line 1935, in dispatch_request
    return self.view_functions[rule.endpoint](**req.view_args)
  File "C:\ильнур\flask-factory\app\codes\routes.py", line 19, in list_decoded
    out = gdsdecoder.decode_gds(line)
  File "C:\ильнур\flask-factory\app\processing\gdsdecoder.py", line 14, in decode_gds
    processors.process_airports(from_to_airports,decoded)
  File "C:\ильнур\flask-factory\app\processing\processors.py", line 40, in process_airports
    raise ValueError
ValueError
Exception on / [GET]
Traceback (most recent call last):
  File "C:\Users\Roman\AppData\Local\Programs\Python\Python38-32\lib\site-packages\flask\app.py", line 2446, in wsgi_app
    response = self.full_dispatch_request()
  File "C:\Users\Roman\AppData\Local\Programs\Python\Python38-32\lib\site-packages\flask\app.py", line 1951, in full_dispatch_request
    rv = self.handle_user_exception(e)
  File "C:\Users\Roman\AppData\Local\Programs\Python\Python38-32\lib\site-packages\flask\app.py", line 1820, in handle_user_exception
    reraise(exc_type, exc_value, tb)
  File "C:\Users\Roman\AppData\Local\Programs\Python\Python38-32\lib\site-packages\flask\_compat.py", line 39, in reraise
    raise value
  File "C:\Users\Roman\AppData\Local\Programs\Python\Python38-32\lib\site-packages\flask\app.py", line 1949, in full_dispatch_request
    rv = self.dispatch_request()
  File "C:\Users\Roman\AppData\Local\Programs\Python\Python38-32\lib\site-packages\flask\app.py", line 1935, in dispatch_request
    return self.view_functions[rule.endpoint](**req.view_args)
  File "C:\ильнур\flask-factory\app\decoder\routes.py", line 14, in decoder
    return render_template("decoder.html",form=form)
  File "C:\Users\Roman\AppData\Local\Programs\Python\Python38-32\lib\site-packages\flask\templating.py", line 137, in render_template
    return _render(
  File "C:\Users\Roman\AppData\Local\Programs\Python\Python38-32\lib\site-packages\flask\templating.py", line 120, in _render
    rv = template.render(context)
  File "C:\Users\Roman\AppData\Local\Programs\Python\Python38-32\lib\site-packages\jinja2\environment.py", line 1090, in render
    self.environment.handle_exception()
  File "C:\Users\Roman\AppData\Local\Programs\Python\Python38-32\lib\site-packages\jinja2\environment.py", line 832, in handle_exception
    reraise(*rewrite_traceback_stack(source=source))
  File "C:\Users\Roman\AppData\Local\Programs\Python\Python38-32\lib\site-packages\jinja2\_compat.py", line 28, in reraise
    raise value.with_traceback(tb)
  File "C:\ильнур\flask-factory\app\decoder\templates\decoder.html", line 2, in top-level template code
    {% import "bootstrap5/form.html" as wtf %}
  File "C:\ильнур\flask-factory\app\templates\base.html", line 18, in top-level template code
    {% block javascript %} {%endblock%}
  File "C:\ильнур\flask-factory\app\decoder\templates\decoder.html", line 13, in block "javascript"
    const base_url  = "{{ url_for('codes.list_decoded') }}";
  File "C:\Users\Roman\AppData\Local\Programs\Python\Python38-32\lib\site-packages\flask\helpers.py", line 370, in url_for
    return appctx.app.handle_url_build_error(error, endpoint, values)
  File "C:\Users\Roman\AppData\Local\Programs\Python\Python38-32\lib\site-packages\flask\app.py", line 2215, in handle_url_build_error
    reraise(exc_type, exc_value, tb)
  File "C:\Users\Roman\AppData\Local\Programs\Python\Python38-32\lib\site-packages\flask\_compat.py", line 39, in reraise
    raise value
  File "C:\Users\Roman\AppData\Local\Programs\Python\Python38-32\lib\site-packages\flask\helpers.py", line 357, in url_for
    rv = url_adapter.build(
  File "C:\Users\Roman\AppData\Local\Programs\Python\Python38-32\lib\site-packages\werkzeug\routing.py", line 2179, in build
    raise BuildError(endpoint, values, method, self)
werkzeug.routing.BuildError: Could not build url for endpoint 'codes.list_decoded'. Did you mean 'codes.grid' instead?
Exception on /api/airports [GET]
Traceback (most recent call last):
  File "C:\Users\Roman\AppData\Local\Programs\Python\Python38-32\lib\site-packages\sqlalchemy\engine\base.py", line 1245, in _execute_context
    self.dialect.do_execute(
  File "C:\Users\Roman\AppData\Local\Programs\Python\Python38-32\lib\site-packages\sqlalchemy\engine\default.py", line 588, in do_execute
    cursor.execute(statement, parameters)
sqlite3.OperationalError: no such table: airports

The above exception was the direct cause of the following exception:

Traceback (most recent call last):
  File "C:\Users\Roman\AppData\Local\Programs\Python\Python38-32\lib\site-packages\flask\app.py", line 2446, in wsgi_app
    response = self.full_dispatch_request()
  File "C:\Users\Roman\AppData\Local\Programs\Python\Python38-32\lib\site-packages\flask\app.py", line 1951, in full_dispatch_request
    rv = self.handle_user_exception(e)
  File "C:\Users\Roman\AppData\Local\Programs\Python\Python38-32\lib\site-packages\flask\app.py", line 1820, in handle_user_exception
    reraise(exc_type, exc_value, tb)
  File "C:\Users\Roman\AppData\Local\Programs\Python\Python38-32\lib\site-packages\flask\_compat.py", line 39, in reraise
    raise value
  File "C:\Users\Roman\AppData\Local\Programs\Python\Python38-32\lib\site-packages\flask\app.py", line 1949, in full_dispatch_request
    rv = self.dispatch_request()
  File "C:\Users\Roman\AppData\Local\Programs\Python\Python38-32\lib\site-packages\flask\app.py", line 1935, in dispatch_request
    return self.view_functions[rule.endpoint](**req.view_args)
  File "C:\Users\Roman\AppData\Local\Programs\Python\Python38-32\lib\site-packages\flask_restless\views.py", line 157, in decorator
    return func(*args, **kw)
  File "C:\Users\Roman\AppData\Local\Programs\Python\Python38-32\lib\site-packages\mimerender.py", line 244, in wrapper
    result = target(*args, **kwargs)
  File "C:\Users\Roman\AppData\Local\Programs\Python\Python38-32\lib\site-packages\flask\views.py", line 89, in view
    return self.dispatch_request(*args, **kwargs)
  File "C:\Users\Roman\AppData\Local\Programs\Python\Python38-32\lib\site-packages\flask\views.py", line 163, in dispatch_request
    return meth(*args, **kwargs)
  File "C:\Users\Roman\AppData\Local\Programs\Python\Python38-32\lib\site-packages\flask_restless\views.py", line 189, in wrapped
    return func(*args, **kw)
  File "C:\Users\Roman\AppData\Local\Programs\Python\Python38-32\lib\site-packages\flask_restless\views.py", line 1239, in get
    return self._search()
  File "C:\Users\Roman\AppData\Local\Programs\Python\Python38-32\lib\site-packages\flask_restless\views.py", line 1194, in _search
    result = self._paginated(result, deep)
  File "C:\Users\Roman\AppData\Local\Programs\Python\Python38-32\lib\site-packages\flask_restless\views.py", line 963, in _paginated
    num_results = count(self.session, instances)
  File "C:\Users\Roman\AppData\Local\Programs\Python\Python38-32\lib\site-packages\flask_restless\helpers.py", line 594, in count
    num_results = session.execute(counts.order_by(None)).scalar()
  File "C:\Users\Roman\AppData\Local\Programs\Python\Python38-32\lib\site-packages\sqlalchemy\orm\scoping.py", line 162, in do
    return getattr(self.registry(), name)(*args, **kwargs)
  File "C:\Users\Roman\AppData\Local\Programs\Python\Python38-32\lib\site-packages\sqlalchemy\orm\session.py", line 1277, in execute
    return self._connection_for_bind(bind, close_with_result=True).execute(
  File "C:\Users\Roman\AppData\Local\Programs\Python\Python38-32\lib\site-packages\sqlalchemy\engine\base.py", line 982, in execute
    return meth(self, multiparams, params)
  File "C:\Users\Roman\AppData\Local\Programs\Python\Python38-32\lib\site-packages\sqlalchemy\sql\elements.py", line 293, in _execute_on_connection
    return connection._execute_clauseelement(self, multiparams, params)
  File "C:\Users\Roman\AppData\Local\Programs\Python\Python38-32\lib\site-packages\sqlalchemy\engine\base.py", line 1095, in _execute_clauseelement
    ret = self._execute_context(
  File "C:\Users\Roman\AppData\Local\Programs\Python\Python38-32\lib\site-packages\sqlalchemy\engine\base.py", line 1249, in _execute_context
    self._handle_dbapi_exception(
  File "C:\Users\Roman\AppData\Local\Programs\Python\Python38-32\lib\site-packages\sqlalchemy\engine\base.py", line 1476, in _handle_dbapi_exception
    util.raise_from_cause(sqlalchemy_exception, exc_info)
  File "C:\Users\Roman\AppData\Local\Programs\Python\Python38-32\lib\site-packages\sqlalchemy\util\compat.py", line 398, in raise_from_cause
    reraise(type(exception), exception, tb=exc_tb, cause=cause)
  File "C:\Users\Roman\AppData\Local\Programs\Python\Python38-32\lib\site-packages\sqlalchemy\util\compat.py", line 152, in reraise
    raise value.with_traceback(tb)
  File "C:\Users\Roman\AppData\Local\Programs\Python\Python38-32\lib\site-packages\sqlalchemy\engine\base.py", line 1245, in _execute_context
    self.dialect.do_execute(
  File "C:\Users\Roman\AppData\Local\Programs\Python\Python38-32\lib\site-packages\sqlalchemy\engine\default.py", line 588, in do_execute
    cursor.execute(statement, parameters)
sqlalchemy.exc.OperationalError: (sqlite3.OperationalError) no such table: airports
[SQL: SELECT count(*) AS count_1 
FROM airports]
(Background on this error at: http://sqlalche.me/e/e3q8)
Exception on /api/airports [GET]
Traceback (most recent call last):
  File "C:\Users\Roman\AppData\Local\Programs\Python\Python38-32\lib\site-packages\sqlalchemy\engine\base.py", line 1245, in _execute_context
    self.dialect.do_execute(
  File "C:\Users\Roman\AppData\Local\Programs\Python\Python38-32\lib\site-packages\sqlalchemy\engine\default.py", line 588, in do_execute
    cursor.execute(statement, parameters)
sqlite3.OperationalError: no such table: airports

The above exception was the direct cause of the following exception:

Traceback (most recent call last):
  File "C:\Users\Roman\AppData\Local\Programs\Python\Python38-32\lib\site-packages\flask\app.py", line 2446, in wsgi_app
    response = self.full_dispatch_request()
  File "C:\Users\Roman\AppData\Local\Programs\Python\Python38-32\lib\site-packages\flask\app.py", line 1951, in full_dispatch_request
    rv = self.handle_user_exception(e)
  File "C:\Users\Roman\AppData\Local\Programs\Python\Python38-32\lib\site-packages\flask\app.py", line 1820, in handle_user_exception
    reraise(exc_type, exc_value, tb)
  File "C:\Users\Roman\AppData\Local\Programs\Python\Python38-32\lib\site-packages\flask\_compat.py", line 39, in reraise
    raise value
  File "C:\Users\Roman\AppData\Local\Programs\Python\Python38-32\lib\site-packages\flask\app.py", line 1949, in full_dispatch_request
    rv = self.dispatch_request()
  File "C:\Users\Roman\AppData\Local\Programs\Python\Python38-32\lib\site-packages\flask\app.py", line 1935, in dispatch_request
    return self.view_functions[rule.endpoint](**req.view_args)
  File "C:\Users\Roman\AppData\Local\Programs\Python\Python38-32\lib\site-packages\flask_restless\views.py", line 157, in decorator
    return func(*args, **kw)
  File "C:\Users\Roman\AppData\Local\Programs\Python\Python38-32\lib\site-packages\mimerender.py", line 244, in wrapper
    result = target(*args, **kwargs)
  File "C:\Users\Roman\AppData\Local\Programs\Python\Python38-32\lib\site-packages\flask\views.py", line 89, in view
    return self.dispatch_request(*args, **kwargs)
  File "C:\Users\Roman\AppData\Local\Programs\Python\Python38-32\lib\site-packages\flask\views.py", line 163, in dispatch_request
    return meth(*args, **kwargs)
  File "C:\Users\Roman\AppData\Local\Programs\Python\Python38-32\lib\site-packages\flask_restless\views.py", line 189, in wrapped
    return func(*args, **kw)
  File "C:\Users\Roman\AppData\Local\Programs\Python\Python38-32\lib\site-packages\flask_restless\views.py", line 1239, in get
    return self._search()
  File "C:\Users\Roman\AppData\Local\Programs\Python\Python38-32\lib\site-packages\flask_restless\views.py", line 1194, in _search
    result = self._paginated(result, deep)
  File "C:\Users\Roman\AppData\Local\Programs\Python\Python38-32\lib\site-packages\flask_restless\views.py", line 963, in _paginated
    num_results = count(self.session, instances)
  File "C:\Users\Roman\AppData\Local\Programs\Python\Python38-32\lib\site-packages\flask_restless\helpers.py", line 594, in count
    num_results = session.execute(counts.order_by(None)).scalar()
  File "C:\Users\Roman\AppData\Local\Programs\Python\Python38-32\lib\site-packages\sqlalchemy\orm\scoping.py", line 162, in do
    return getattr(self.registry(), name)(*args, **kwargs)
  File "C:\Users\Roman\AppData\Local\Programs\Python\Python38-32\lib\site-packages\sqlalchemy\orm\session.py", line 1277, in execute
    return self._connection_for_bind(bind, close_with_result=True).execute(
  File "C:\Users\Roman\AppData\Local\Programs\Python\Python38-32\lib\site-packages\sqlalchemy\engine\base.py", line 982, in execute
    return meth(self, multiparams, params)
  File "C:\Users\Roman\AppData\Local\Programs\Python\Python38-32\lib\site-packages\sqlalchemy\sql\elements.py", line 293, in _execute_on_connection
    return connection._execute_clauseelement(self, multiparams, params)
  File "C:\Users\Roman\AppData\Local\Programs\Python\Python38-32\lib\site-packages\sqlalchemy\engine\base.py", line 1095, in _execute_clauseelement
    ret = self._execute_context(
  File "C:\Users\Roman\AppData\Local\Programs\Python\Python38-32\lib\site-packages\sqlalchemy\engine\base.py", line 1249, in _execute_context
    self._handle_dbapi_exception(
  File "C:\Users\Roman\AppData\Local\Programs\Python\Python38-32\lib\site-packages\sqlalchemy\engine\base.py", line 1476, in _handle_dbapi_exception
    util.raise_from_cause(sqlalchemy_exception, exc_info)
  File "C:\Users\Roman\AppData\Local\Programs\Python\Python38-32\lib\site-packages\sqlalchemy\util\compat.py", line 398, in raise_from_cause
    reraise(type(exception), exception, tb=exc_tb, cause=cause)
  File "C:\Users\Roman\AppData\Local\Programs\Python\Python38-32\lib\site-packages\sqlalchemy\util\compat.py", line 152, in reraise
    raise value.with_traceback(tb)
  File "C:\Users\Roman\AppData\Local\Programs\Python\Python38-32\lib\site-packages\sqlalchemy\engine\base.py", line 1245, in _execute_context
    self.dialect.do_execute(
  File "C:\Users\Roman\AppData\Local\Programs\Python\Python38-32\lib\site-packages\sqlalchemy\engine\default.py", line 588, in do_execute
    cursor.execute(statement, parameters)
sqlalchemy.exc.OperationalError: (sqlite3.OperationalError) no such table: airports
[SQL: SELECT count(*) AS count_1 
FROM airports]
(Background on this error at: http://sqlalche.me/e/e3q8)
Exception on /api/airports [GET]
Traceback (most recent call last):
  File "C:\Users\Roman\AppData\Local\Programs\Python\Python38-32\lib\site-packages\sqlalchemy\engine\base.py", line 1245, in _execute_context
    self.dialect.do_execute(
  File "C:\Users\Roman\AppData\Local\Programs\Python\Python38-32\lib\site-packages\sqlalchemy\engine\default.py", line 588, in do_execute
    cursor.execute(statement, parameters)
sqlite3.OperationalError: no such table: airports

The above exception was the direct cause of the following exception:

Traceback (most recent call last):
  File "C:\Users\Roman\AppData\Local\Programs\Python\Python38-32\lib\site-packages\flask\app.py", line 2446, in wsgi_app
    response = self.full_dispatch_request()
  File "C:\Users\Roman\AppData\Local\Programs\Python\Python38-32\lib\site-packages\flask\app.py", line 1951, in full_dispatch_request
    rv = self.handle_user_exception(e)
  File "C:\Users\Roman\AppData\Local\Programs\Python\Python38-32\lib\site-packages\flask\app.py", line 1820, in handle_user_exception
    reraise(exc_type, exc_value, tb)
  File "C:\Users\Roman\AppData\Local\Programs\Python\Python38-32\lib\site-packages\flask\_compat.py", line 39, in reraise
    raise value
  File "C:\Users\Roman\AppData\Local\Programs\Python\Python38-32\lib\site-packages\flask\app.py", line 1949, in full_dispatch_request
    rv = self.dispatch_request()
  File "C:\Users\Roman\AppData\Local\Programs\Python\Python38-32\lib\site-packages\flask\app.py", line 1935, in dispatch_request
    return self.view_functions[rule.endpoint](**req.view_args)
  File "C:\Users\Roman\AppData\Local\Programs\Python\Python38-32\lib\site-packages\flask_restless\views.py", line 157, in decorator
    return func(*args, **kw)
  File "C:\Users\Roman\AppData\Local\Programs\Python\Python38-32\lib\site-packages\mimerender.py", line 244, in wrapper
    result = target(*args, **kwargs)
  File "C:\Users\Roman\AppData\Local\Programs\Python\Python38-32\lib\site-packages\flask\views.py", line 89, in view
    return self.dispatch_request(*args, **kwargs)
  File "C:\Users\Roman\AppData\Local\Programs\Python\Python38-32\lib\site-packages\flask\views.py", line 163, in dispatch_request
    return meth(*args, **kwargs)
  File "C:\Users\Roman\AppData\Local\Programs\Python\Python38-32\lib\site-packages\flask_restless\views.py", line 189, in wrapped
    return func(*args, **kw)
  File "C:\Users\Roman\AppData\Local\Programs\Python\Python38-32\lib\site-packages\flask_restless\views.py", line 1239, in get
    return self._search()
  File "C:\Users\Roman\AppData\Local\Programs\Python\Python38-32\lib\site-packages\flask_restless\views.py", line 1194, in _search
    result = self._paginated(result, deep)
  File "C:\Users\Roman\AppData\Local\Programs\Python\Python38-32\lib\site-packages\flask_restless\views.py", line 963, in _paginated
    num_results = count(self.session, instances)
  File "C:\Users\Roman\AppData\Local\Programs\Python\Python38-32\lib\site-packages\flask_restless\helpers.py", line 594, in count
    num_results = session.execute(counts.order_by(None)).scalar()
  File "C:\Users\Roman\AppData\Local\Programs\Python\Python38-32\lib\site-packages\sqlalchemy\orm\scoping.py", line 162, in do
    return getattr(self.registry(), name)(*args, **kwargs)
  File "C:\Users\Roman\AppData\Local\Programs\Python\Python38-32\lib\site-packages\sqlalchemy\orm\session.py", line 1277, in execute
    return self._connection_for_bind(bind, close_with_result=True).execute(
  File "C:\Users\Roman\AppData\Local\Programs\Python\Python38-32\lib\site-packages\sqlalchemy\engine\base.py", line 982, in execute
    return meth(self, multiparams, params)
  File "C:\Users\Roman\AppData\Local\Programs\Python\Python38-32\lib\site-packages\sqlalchemy\sql\elements.py", line 293, in _execute_on_connection
    return connection._execute_clauseelement(self, multiparams, params)
  File "C:\Users\Roman\AppData\Local\Programs\Python\Python38-32\lib\site-packages\sqlalchemy\engine\base.py", line 1095, in _execute_clauseelement
    ret = self._execute_context(
  File "C:\Users\Roman\AppData\Local\Programs\Python\Python38-32\lib\site-packages\sqlalchemy\engine\base.py", line 1249, in _execute_context
    self._handle_dbapi_exception(
  File "C:\Users\Roman\AppData\Local\Programs\Python\Python38-32\lib\site-packages\sqlalchemy\engine\base.py", line 1476, in _handle_dbapi_exception
    util.raise_from_cause(sqlalchemy_exception, exc_info)
  File "C:\Users\Roman\AppData\Local\Programs\Python\Python38-32\lib\site-packages\sqlalchemy\util\compat.py", line 398, in raise_from_cause
    reraise(type(exception), exception, tb=exc_tb, cause=cause)
  File "C:\Users\Roman\AppData\Local\Programs\Python\Python38-32\lib\site-packages\sqlalchemy\util\compat.py", line 152, in reraise
    raise value.with_traceback(tb)
  File "C:\Users\Roman\AppData\Local\Programs\Python\Python38-32\lib\site-packages\sqlalchemy\engine\base.py", line 1245, in _execute_context
    self.dialect.do_execute(
  File "C:\Users\Roman\AppData\Local\Programs\Python\Python38-32\lib\site-packages\sqlalchemy\engine\default.py", line 588, in do_execute
    cursor.execute(statement, parameters)
sqlalchemy.exc.OperationalError: (sqlite3.OperationalError) no such table: airports
[SQL: SELECT count(*) AS count_1 
FROM airports]
(Background on this error at: http://sqlalche.me/e/e3q8)
sqlite:///C:\Users\Roman\.local\share\flask-gridify-example\db3.sqlite
C:\Users\Roman\.local\share\flask-gridify-example\db3.sqlite
sqlite:///C:\Users\Roman\.local\share\flask-factory\db3.sqlite
C:\Users\Roman\.local\share\flask-factory\db3.sqlite
<SQLAlchemy engine=sqlite:///C:\ильнур\flask-factory\airports.db>
<SQLAlchemy engine=sqlite:///C:\ильнур\flask-factory\airports.db>
<SQLAlchemy engine=sqlite:///C:\ильнур\flask-factory\airports.db>
<SQLAlchemy engine=sqlite:///C:\ильнур\flask-factory\airports.db>
Exception on / [GET]
Traceback (most recent call last):
  File "C:\Users\Roman\AppData\Local\Programs\Python\Python38-32\lib\site-packages\flask\app.py", line 2446, in wsgi_app
    response = self.full_dispatch_request()
  File "C:\Users\Roman\AppData\Local\Programs\Python\Python38-32\lib\site-packages\flask\app.py", line 1951, in full_dispatch_request
    rv = self.handle_user_exception(e)
  File "C:\Users\Roman\AppData\Local\Programs\Python\Python38-32\lib\site-packages\flask\app.py", line 1820, in handle_user_exception
    reraise(exc_type, exc_value, tb)
  File "C:\Users\Roman\AppData\Local\Programs\Python\Python38-32\lib\site-packages\flask\_compat.py", line 39, in reraise
    raise value
  File "C:\Users\Roman\AppData\Local\Programs\Python\Python38-32\lib\site-packages\flask\app.py", line 1949, in full_dispatch_request
    rv = self.dispatch_request()
  File "C:\Users\Roman\AppData\Local\Programs\Python\Python38-32\lib\site-packages\flask\app.py", line 1935, in dispatch_request
    return self.view_functions[rule.endpoint](**req.view_args)
  File "C:\ильнур\flask-factory\app\decoder\routes.py", line 14, in decoder
    return render_template("decoder.html",form=form)
  File "C:\Users\Roman\AppData\Local\Programs\Python\Python38-32\lib\site-packages\flask\templating.py", line 137, in render_template
    return _render(
  File "C:\Users\Roman\AppData\Local\Programs\Python\Python38-32\lib\site-packages\flask\templating.py", line 120, in _render
    rv = template.render(context)
  File "C:\Users\Roman\AppData\Local\Programs\Python\Python38-32\lib\site-packages\jinja2\environment.py", line 1090, in render
    self.environment.handle_exception()
  File "C:\Users\Roman\AppData\Local\Programs\Python\Python38-32\lib\site-packages\jinja2\environment.py", line 832, in handle_exception
    reraise(*rewrite_traceback_stack(source=source))
  File "C:\Users\Roman\AppData\Local\Programs\Python\Python38-32\lib\site-packages\jinja2\_compat.py", line 28, in reraise
    raise value.with_traceback(tb)
  File "C:\ильнур\flask-factory\app\decoder\templates\decoder.html", line 2, in top-level template code
    {% import "bootstrap5/form.html" as wtf %}
  File "C:\ильнур\flask-factory\app\templates\base.html", line 18, in top-level template code
    {% block javascript %} {%endblock%}
  File "C:\ильнур\flask-factory\app\decoder\templates\decoder.html", line 13, in block "javascript"
    const base_url  = "{{ url_for('codes.list_decoded') }}";
  File "C:\Users\Roman\AppData\Local\Programs\Python\Python38-32\lib\site-packages\flask\helpers.py", line 370, in url_for
    return appctx.app.handle_url_build_error(error, endpoint, values)
  File "C:\Users\Roman\AppData\Local\Programs\Python\Python38-32\lib\site-packages\flask\app.py", line 2215, in handle_url_build_error
    reraise(exc_type, exc_value, tb)
  File "C:\Users\Roman\AppData\Local\Programs\Python\Python38-32\lib\site-packages\flask\_compat.py", line 39, in reraise
    raise value
  File "C:\Users\Roman\AppData\Local\Programs\Python\Python38-32\lib\site-packages\flask\helpers.py", line 357, in url_for
    rv = url_adapter.build(
  File "C:\Users\Roman\AppData\Local\Programs\Python\Python38-32\lib\site-packages\werkzeug\routing.py", line 2179, in build
    raise BuildError(endpoint, values, method, self)
werkzeug.routing.BuildError: Could not build url for endpoint 'codes.list_decoded'. Did you mean 'codes.grid' instead?
<SQLAlchemy engine=sqlite:///C:\ильнур\flask-factory\airports.db>
<SQLAlchemy engine=sqlite:///C:\ильнур\flask-factory\airports.db>
<SQLAlchemy engine=sqlite:///C:\ильнур\flask-factory\airports.db>
<SQLAlchemy engine=sqlite:///C:\ильнур\flask-factory\airports.db>
<SQLAlchemy engine=sqlite:///C:\ильнур\flask-factory\airports.db>
<SQLAlchemy engine=sqlite:///C:\ильнур\flask-factory\airports.db>
<SQLAlchemy engine=sqlite:///C:\ильнур\flask-factory\airports.db>
<SQLAlchemy engine=sqlite:///C:\ильнур\flask-factory\airports.db>
<SQLAlchemy engine=sqlite:///C:\ильнур\flask-factory\airports.db>
<SQLAlchemy engine=sqlite:///C:\ильнур\flask-factory\airports.db>
<SQLAlchemy engine=sqlite:///C:\ильнур\flask-factory\airports.db>
<SQLAlchemy engine=sqlite:///C:\ильнур\flask-factory\airports.db>
<SQLAlchemy engine=sqlite:///C:\ильнур\flask-factory\airports.db>
<SQLAlchemy engine=sqlite:///C:\ильнур\flask-factory\airports.db>
<SQLAlchemy engine=sqlite:///C:\ильнур\flask-factory\airports.db>
<SQLAlchemy engine=sqlite:///C:\ильнур\flask-factory\airports.db>
<SQLAlchemy engine=sqlite:///C:\ильнур\flask-factory\airports.db>
<SQLAlchemy engine=sqlite:///C:\ильнур\flask-factory\airports.db>
['__class__', '__delattr__', '__dict__', '__dir__', '__doc__', '__eq__', '__format__', '__ge__', '__getattribute__', '__gt__', '__hash__', '__init__', '__init_subclass__', '__le__', '__lt__', '__module__', '__ne__', '__new__', '__reduce__', '__reduce_ex__', '__repr__', '__setattr__', '__sizeof__', '__str__', '__subclasshook__', '__weakref__', '_index_sort_exprs', '_insp', '_reflect_check_constraints', '_reflect_col_sequence', '_reflect_column', '_reflect_fk', '_reflect_indexes', '_reflect_pk', '_reflect_table_comment', '_reflect_unique_constraints', 'bind', 'default_schema_name', 'dialect', 'engine', 'from_engine', 'get_check_constraints', 'get_columns', 'get_foreign_keys', 'get_indexes', 'get_pk_constraint', 'get_primary_keys', 'get_schema_names', 'get_sorted_table_and_fkc_names', 'get_table_comment', 'get_table_names', 'get_table_options', 'get_temp_table_names', 'get_temp_view_names', 'get_unique_constraints', 'get_view_definition', 'get_view_names', 'info_cache', 'reflecttable']
['__class__', '__delattr__', '__dict__', '__dir__', '__doc__', '__eq__', '__format__', '__ge__', '__getattribute__', '__gt__', '__hash__', '__init__', '__init_subclass__', '__le__', '__lt__', '__module__', '__ne__', '__new__', '__reduce__', '__reduce_ex__', '__repr__', '__setattr__', '__sizeof__', '__str__', '__subclasshook__', '__weakref__', '_index_sort_exprs', '_insp', '_reflect_check_constraints', '_reflect_col_sequence', '_reflect_column', '_reflect_fk', '_reflect_indexes', '_reflect_pk', '_reflect_table_comment', '_reflect_unique_constraints', 'bind', 'default_schema_name', 'dialect', 'engine', 'from_engine', 'get_check_constraints', 'get_columns', 'get_foreign_keys', 'get_indexes', 'get_pk_constraint', 'get_primary_keys', 'get_schema_names', 'get_sorted_table_and_fkc_names', 'get_table_comment', 'get_table_names', 'get_table_options', 'get_temp_table_names', 'get_temp_view_names', 'get_unique_constraints', 'get_view_definition', 'get_view_names', 'info_cache', 'reflecttable']
['__class__', '__delattr__', '__dict__', '__dir__', '__doc__', '__eq__', '__format__', '__ge__', '__getattribute__', '__gt__', '__hash__', '__init__', '__init_subclass__', '__le__', '__lt__', '__module__', '__ne__', '__new__', '__reduce__', '__reduce_ex__', '__repr__', '__setattr__', '__sizeof__', '__str__', '__subclasshook__', '__weakref__', '_index_sort_exprs', '_insp', '_reflect_check_constraints', '_reflect_col_sequence', '_reflect_column', '_reflect_fk', '_reflect_indexes', '_reflect_pk', '_reflect_table_comment', '_reflect_unique_constraints', 'bind', 'default_schema_name', 'dialect', 'engine', 'from_engine', 'get_check_constraints', 'get_columns', 'get_foreign_keys', 'get_indexes', 'get_pk_constraint', 'get_primary_keys', 'get_schema_names', 'get_sorted_table_and_fkc_names', 'get_table_comment', 'get_table_names', 'get_table_options', 'get_temp_table_names', 'get_temp_view_names', 'get_unique_constraints', 'get_view_definition', 'get_view_names', 'info_cache', 'reflecttable']
Initialized the database!
['__class__', '__delattr__', '__dict__', '__dir__', '__doc__', '__eq__', '__format__', '__ge__', '__getattribute__', '__gt__', '__hash__', '__init__', '__init_subclass__', '__le__', '__lt__', '__module__', '__ne__', '__new__', '__reduce__', '__reduce_ex__', '__repr__', '__setattr__', '__sizeof__', '__str__', '__subclasshook__', '__weakref__', '_index_sort_exprs', '_insp', '_reflect_check_constraints', '_reflect_col_sequence', '_reflect_column', '_reflect_fk', '_reflect_indexes', '_reflect_pk', '_reflect_table_comment', '_reflect_unique_constraints', 'bind', 'default_schema_name', 'dialect', 'engine', 'from_engine', 'get_check_constraints', 'get_columns', 'get_foreign_keys', 'get_indexes', 'get_pk_constraint', 'get_primary_keys', 'get_schema_names', 'get_sorted_table_and_fkc_names', 'get_table_comment', 'get_table_names', 'get_table_options', 'get_temp_table_names', 'get_temp_view_names', 'get_unique_constraints', 'get_view_definition', 'get_view_names', 'info_cache', 'reflecttable']
Initialized the database!
['__class__', '__delattr__', '__dict__', '__dir__', '__doc__', '__eq__', '__format__', '__ge__', '__getattribute__', '__gt__', '__hash__', '__init__', '__init_subclass__', '__le__', '__lt__', '__module__', '__ne__', '__new__', '__reduce__', '__reduce_ex__', '__repr__', '__setattr__', '__sizeof__', '__str__', '__subclasshook__', '__weakref__', '_index_sort_exprs', '_insp', '_reflect_check_constraints', '_reflect_col_sequence', '_reflect_column', '_reflect_fk', '_reflect_indexes', '_reflect_pk', '_reflect_table_comment', '_reflect_unique_constraints', 'bind', 'default_schema_name', 'dialect', 'engine', 'from_engine', 'get_check_constraints', 'get_columns', 'get_foreign_keys', 'get_indexes', 'get_pk_constraint', 'get_primary_keys', 'get_schema_names', 'get_sorted_table_and_fkc_names', 'get_table_comment', 'get_table_names', 'get_table_options', 'get_temp_table_names', 'get_temp_view_names', 'get_unique_constraints', 'get_view_definition', 'get_view_names', 'info_cache', 'reflecttable']
['__class__', '__delattr__', '__dict__', '__dir__', '__doc__', '__eq__', '__format__', '__ge__', '__getattribute__', '__gt__', '__hash__', '__init__', '__init_subclass__', '__le__', '__lt__', '__module__', '__ne__', '__new__', '__reduce__', '__reduce_ex__', '__repr__', '__setattr__', '__sizeof__', '__str__', '__subclasshook__', '__weakref__', '_index_sort_exprs', '_insp', '_reflect_check_constraints', '_reflect_col_sequence', '_reflect_column', '_reflect_fk', '_reflect_indexes', '_reflect_pk', '_reflect_table_comment', '_reflect_unique_constraints', 'bind', 'default_schema_name', 'dialect', 'engine', 'from_engine', 'get_check_constraints', 'get_columns', 'get_foreign_keys', 'get_indexes', 'get_pk_constraint', 'get_primary_keys', 'get_schema_names', 'get_sorted_table_and_fkc_names', 'get_table_comment', 'get_table_names', 'get_table_options', 'get_temp_table_names', 'get_temp_view_names', 'get_unique_constraints', 'get_view_definition', 'get_view_names', 'info_cache', 'reflecttable']
['__class__', '__delattr__', '__dict__', '__dir__', '__doc__', '__eq__', '__format__', '__ge__', '__getattribute__', '__gt__', '__hash__', '__init__', '__init_subclass__', '__le__', '__lt__', '__module__', '__ne__', '__new__', '__reduce__', '__reduce_ex__', '__repr__', '__setattr__', '__sizeof__', '__str__', '__subclasshook__', '__weakref__', '_index_sort_exprs', '_insp', '_reflect_check_constraints', '_reflect_col_sequence', '_reflect_column', '_reflect_fk', '_reflect_indexes', '_reflect_pk', '_reflect_table_comment', '_reflect_unique_constraints', 'bind', 'default_schema_name', 'dialect', 'engine', 'from_engine', 'get_check_constraints', 'get_columns', 'get_foreign_keys', 'get_indexes', 'get_pk_constraint', 'get_primary_keys', 'get_schema_names', 'get_sorted_table_and_fkc_names', 'get_table_comment', 'get_table_names', 'get_table_options', 'get_temp_table_names', 'get_temp_view_names', 'get_unique_constraints', 'get_view_definition', 'get_view_names', 'info_cache', 'reflecttable']
['__class__', '__delattr__', '__dict__', '__dir__', '__doc__', '__eq__', '__format__', '__ge__', '__getattribute__', '__gt__', '__hash__', '__init__', '__init_subclass__', '__le__', '__lt__', '__module__', '__ne__', '__new__', '__reduce__', '__reduce_ex__', '__repr__', '__setattr__', '__sizeof__', '__str__', '__subclasshook__', '__weakref__', '_index_sort_exprs', '_insp', '_reflect_check_constraints', '_reflect_col_sequence', '_reflect_column', '_reflect_fk', '_reflect_indexes', '_reflect_pk', '_reflect_table_comment', '_reflect_unique_constraints', 'bind', 'default_schema_name', 'dialect', 'engine', 'from_engine', 'get_check_constraints', 'get_columns', 'get_foreign_keys', 'get_indexes', 'get_pk_constraint', 'get_primary_keys', 'get_schema_names', 'get_sorted_table_and_fkc_names', 'get_table_comment', 'get_table_names', 'get_table_options', 'get_temp_table_names', 'get_temp_view_names', 'get_unique_constraints', 'get_view_definition', 'get_view_names', 'info_cache', 'reflecttable']
Database already contains the airport table.
['__class__', '__delattr__', '__dict__', '__dir__', '__doc__', '__eq__', '__format__', '__ge__', '__getattribute__', '__gt__', '__hash__', '__init__', '__init_subclass__', '__le__', '__lt__', '__module__', '__ne__', '__new__', '__reduce__', '__reduce_ex__', '__repr__', '__setattr__', '__sizeof__', '__str__', '__subclasshook__', '__weakref__', '_index_sort_exprs', '_insp', '_reflect_check_constraints', '_reflect_col_sequence', '_reflect_column', '_reflect_fk', '_reflect_indexes', '_reflect_pk', '_reflect_table_comment', '_reflect_unique_constraints', 'bind', 'default_schema_name', 'dialect', 'engine', 'from_engine', 'get_check_constraints', 'get_columns', 'get_foreign_keys', 'get_indexes', 'get_pk_constraint', 'get_primary_keys', 'get_schema_names', 'get_sorted_table_and_fkc_names', 'get_table_comment', 'get_table_names', 'get_table_options', 'get_temp_table_names', 'get_temp_view_names', 'get_unique_constraints', 'get_view_definition', 'get_view_names', 'info_cache', 'reflecttable']
Database already contains the airport table.
